<mujoco model="bhand_model">
  <compiler angle="radian" meshdir="/home/yareeez/AIST-hand/robot/hands/barrett_hand/"/>

  <asset>
    <mesh name="base_link" content_type="model/obj" file="meshes/visual/base_link.obj"/>
    <mesh name="base_link_cylinder" content_type="model/obj" file="meshes/collision/base_link_cylinder.obj"/>
    <mesh name="prox_link" content_type="model/obj" file="meshes/visual/prox_link.obj"/>
    <mesh name="prox_link_cylinder" content_type="model/obj" file="meshes/collision/prox_link_cylinder.obj"/>
    <mesh name="med_link" content_type="model/obj" file="meshes/visual/med_link.obj"/>
    <mesh name="dist_link" content_type="model/obj" file="meshes/visual/dist_link.obj"/>
  </asset>

  <worldbody>
    <geom type="mesh" contype="0" conaffinity="0" group="1" density="0" mesh="base_link"/>
    <geom type="mesh" mesh="base_link_cylinder"/>
    <geom size="0.013 0.054 0.013" pos="0 -0.011 0.054" type="box"/>
    <geom size="0.038 0.023 0.007" pos="0 0 0.072" type="box"/>
    <geom size="0.013 0.01 0.005" pos="0 0.032 0.068" quat="0.981048 -0.193767 0 0" type="box"/>
    <geom size="0.013 0.01 0.005" pos="0 -0.035 0.07" quat="0.870293 -0.492535 0 0" type="box"/>
    <body name="finger_1_prox_link" pos="0.025 0 0.0415" quat="0.707105 0 0 -0.707108">
      <inertial pos="-0.288649 0.00099838 0.171253" quat="0.54962 0.438092 0.426 0.569664" mass="0.561431" diaginertia="0.000339591 0.000307549 9.05655e-05"/>
      <joint name="finger_1_prox_joint" pos="0 0 0" axis="0 0 1" range="-3.14 0"/>
      <geom type="mesh" contype="0" conaffinity="0" group="1" density="0" mesh="prox_link"/>
      <geom type="mesh" mesh="prox_link_cylinder"/>
      <geom size="0.035 0.012 0.013" pos="-0.029 0 0.012" type="box"/>
      <geom size="0.01 0.013 0.005" pos="-0.036 0 0.03" quat="0.870539 0 0.4921 0" type="box"/>
      <body name="finger_1_med_liink" pos="-0.05 0 0.0339" quat="0.707105 0.707108 0 0">
        <inertial pos="-0.0309182 0.0019693 0.00074337" quat="-0.0214282 0.707188 0.0177553 0.706477" mass="0.313211" diaginertia="0.000177657 0.000174065 2.13826e-05"/>
        <joint name="finger_1_med_joint" pos="0 0 0" axis="0 0 1" range="-2.44 0"/>
        <geom type="mesh" contype="0" conaffinity="0" group="1" density="0" mesh="med_link"/>
        <geom size="0.018 0.012 0.009" pos="-0.04 0.003 0.001" type="box"/>
        <geom size="0.016 0.011 0.005" pos="-0.006 0.001 0.001" type="box"/>
        <geom size="0.01 0.011 0.005" pos="-0.068 0.003 0.001" type="box"/>
        <geom size="0.004 0.011 0.009" pos="-0.019 0.001 0.001" type="box"/>
        <body name="finger_1_dist_link" pos="-0.069936 0.003 0" quat="1 0 0 0">
          <inertial pos="-0.0183315 0.0175634 0.000497128" quat="0.251159 0.315294 0.632663 0.661246" mass="0.193423" diaginertia="6.47196e-05 5.98921e-05 1.29472e-05"/>
          <joint name="finger_1_dist_joint" pos="0 0 0" axis="0 0 1" range="-0.785 0"/>
          <geom type="mesh" contype="0" conaffinity="0" group="1" density="0" mesh="dist_link"/>
          <geom size="0.007 0.019 0.01" pos="-0.022 0.023 0" quat="0.900708 0 0 0.434425" type="box"/>
          <geom size="0.009 0.011 0.01" pos="-0.002 0.002 0" quat="0.925554 0 0 0.378616" type="box"/>
          <geom size="0.006 0.006 0.01" pos="-0.038 0.034 0" quat="0.691668 0 0 0.722215" type="box"/>
        </body>
      </body>
    </body>
    <body name="finger_2_prox_link" pos="-0.025 0 0.0415" quat="0.707105 0 0 -0.707108">
      <inertial pos="-0.288649 0.00099838 0.171253" quat="0.54962 0.438092 0.426 0.569664" mass="0.561431" diaginertia="0.000339591 0.000307549 9.05655e-05"/>
      <joint name="finger_2_prox_joint" pos="0 0 0" axis="0 0 1" range="0 3.14"/>
      <geom type="mesh" contype="0" conaffinity="0" group="1" density="0" mesh="prox_link"/>
      <geom type="mesh" mesh="prox_link_cylinder"/>
      <geom size="0.035 0.012 0.013" pos="-0.029 0 0.012" type="box"/>
      <geom size="0.01 0.013 0.005" pos="-0.036 0 0.03" quat="0.870539 0 0.4921 0" type="box"/>
      <body name="finger_2_med_link" pos="-0.05 0 0.0339" quat="0.707105 0.707108 0 0">
        <inertial pos="-0.0309061 0.00214998 0.00074337" quat="-0.0236473 0.707137 0.0196672 0.706407" mass="0.313211" diaginertia="0.000177657 0.000174065 2.13826e-05"/>
        <joint name="finger_2_med_joint" pos="0 0 0" axis="0 0 1" range="-2.44 0"/>
        <geom type="mesh" contype="0" conaffinity="0" group="1" density="0" mesh="med_link"/>
        <geom size="0.018 0.012 0.009" pos="-0.04 0.003 0.001" type="box"/>
        <geom size="0.016 0.011 0.005" pos="-0.006 0.001 0.001" type="box"/>
        <geom size="0.01 0.011 0.005" pos="-0.068 0.003 0.001" type="box"/>
        <geom size="0.004 0.011 0.009" pos="-0.019 0.001 0.001" type="box"/>
        <body name="finger_2_dist_link" pos="-0.069917 0.0034087 0">
          <inertial pos="-0.0181941 0.0177057 0.000497128" quat="0.248532 0.312878 0.633924 0.662178" mass="0.193423" diaginertia="6.47197e-05 5.9892e-05 1.29472e-05"/>
          <joint name="finger_2_dist_joint" pos="0 0 0" axis="0 0 1" range="-0.785 0"/>
          <geom type="mesh" contype="0" conaffinity="0" group="1" density="0" mesh="dist_link"/>
          <geom size="0.007 0.019 0.01" pos="-0.022 0.023 0" quat="0.900708 0 0 0.434425" type="box"/>
          <geom size="0.009 0.011 0.01" pos="-0.002 0.002 0" quat="0.925554 0 0 0.378616" type="box"/>
          <geom size="0.006 0.006 0.01" pos="-0.038 0.034 0" quat="0.691668 0 0 0.722215" type="box"/>
        </body>
      </body>
    </body>
    <body name="finger_3_med_link" pos="0 -0.05 0.0754" quat="0.499998 0.5 0.500002 0.5">
      <inertial pos="-0.0309182 0.0019693 0.00074337" quat="-0.0214282 0.707188 0.0177553 0.706477" mass="0.313211" diaginertia="0.000177657 0.000174065 2.13826e-05"/>
      <joint name="finger_3_med_joint" pos="0 0 0" axis="0 0 1" range="-2.44 0"/>
      <geom type="mesh" contype="0" conaffinity="0" group="1" density="0" mesh="med_link"/>
      <geom size="0.018 0.012 0.009" pos="-0.04 0.003 0.001" type="box"/>
      <geom size="0.016 0.011 0.005" pos="-0.006 0.001 0.001" type="box"/>
      <geom size="0.01 0.011 0.005" pos="-0.068 0.003 0.001" type="box"/>
      <geom size="0.004 0.011 0.009" pos="-0.019 0.001 0.001" type="box"/>
      <body name="finger_3_dist_link" pos="-0.069936 0.003 0">
        <inertial pos="-0.0183315 0.0175634 0.000497128" quat="0.251159 0.315294 0.632663 0.661246" mass="0.193423" diaginertia="6.47196e-05 5.98921e-05 1.29472e-05"/>
        <joint name="finger_3_dist_joint" pos="0 0 0" axis="0 0 1" range="-0.785 0"/>
        <geom type="mesh" contype="0" conaffinity="0" group="1" density="0" mesh="dist_link"/>
        <geom size="0.007 0.019 0.01" pos="-0.022 0.023 0" quat="0.900708 0 0 0.434425" type="box"/>
        <geom size="0.009 0.011 0.01" pos="-0.002 0.002 0" quat="0.925554 0 0 0.378616" type="box"/>
        <geom size="0.006 0.006 0.01" pos="-0.038 0.034 0" quat="0.691668 0 0 0.722215" type="box"/>
      </body>
    </body>
  </worldbody>
  <contact>
    <exclude body1="world" body2="finger_1_prox_link"/>
    <exclude body1="finger_1_prox_link" body2="finger_1_med_liink"/>
    <exclude body1="finger_1_med_liink" body2="finger_1_dist_link"/>
    <exclude body1="world" body2="finger_2_prox_link"/>
    <exclude body1="finger_2_prox_link" body2="finger_2_med_link"/>
    <exclude body1="finger_2_med_link" body2="finger_2_dist_link"/>
    <exclude body1="world" body2="finger_3_med_link"/>
    <exclude body1="finger_3_med_link" body2="finger_3_dist_link"/>
  </contact>
</mujoco>
